<?xml version="1.0" encoding="utf-8"?>
<!-- This URDF was automatically created by SolidWorks to URDF Exporter! Originally created by Stephen Brawner (brawner@gmail.com) 
     Commit Version: 1.5.1-0-g916b5db  Build Version: 1.5.7152.31018
     For more information, please see http://wiki.ros.org/sw_urdf_exporter -->
<robot
  name="stab" xmlns:xacro="http://ros.org/wiki/xacro">

<!-- ########### Defining the colors used in this robot ########### -->

  <material name="White">
      <color rgba="0.898039215686275 0.917647058823529 0.929411764705882 1"/>
  </material>

<!-- ##########################link########################## -->
  <link
    name="base_link">
    <inertial>
      <origin
        xyz="-0.267622237083787 0.0200000000000051 0.200000000000011"
        rpy="0 0 0" />
      <mass
        value="4.39348226818734E-05" />
      <inertia
        ixx="3.28704519934978E-11"
        ixy="-8.15804703511327E-22"
        ixz="1.61286938235907E-21"
        iyy="3.30462552559842E-10"
        iyz="-3.68952400699453E-27"
        izz="3.30462552559842E-10" />
    </inertial>
    <visual>
      <origin
        xyz="0 0 0"
        rpy="0 0 0" />
      <geometry>
        <mesh
          filename="package://robot_description/meshes/base_link.STL" />
      </geometry>
      <material
        name="">
        <color
          rgba="1 1 1 1" />
      </material>
    </visual>
    <collision>
      <origin
        xyz="0 0 0"
        rpy="0 0 0" />
      <geometry>
        <mesh
          filename="package://robot_description/meshes/base_link.STL" />
      </geometry>
    </collision>
  </link>

  <link
    name="Link1">
    <inertial>
      <origin
        xyz="0.078312 0.0074766 0.3645"
        rpy="0 0 0" />
      <mass
        value="0.013314" />
      <inertia
        ixx="6.1721E-07"
        ixy="4.3741E-08"
        ixz="-2.209E-08"
        iyy="4.6562E-07"
        iyz="8.2426E-08"
        izz="6.8481E-07" />
    </inertial>
    <visual>
      <origin
        xyz="0 0 0"
        rpy="0 0 0" />
      <geometry>
        <mesh
          filename="package://robot_description/meshes/Link1.STL" />
      </geometry>
      <material
        name="">
        <color
          rgba="1 1 1 1" />
      </material>
    </visual>
    <collision>
      <origin
        xyz="0 0 0"
        rpy="0 0 0" />
      <geometry>
        <mesh
          filename="package://robot_description/meshes/Link1.STL" />
      </geometry>
    </collision>
  </link>
  <joint
    name="joint_1"
    type="revolute">
    <origin
      xyz="0 0 0.347"
      rpy="0 0 0" />
    <parent
      link="base_link" />
    <child
      link="Link1" />
    <axis
      xyz="0 0 -1" />
    <limit
      lower="-3.14"
      upper="3.14"
      effort="100000"
      velocity="2" />
  </joint>

  <link
    name="Link2">
    <inertial>
      <origin
        xyz="746890000000 988550000000 175200000000"
        rpy="0 0 0" />
      <mass
        value="1.0511E+23" />
      <inertia
        ixx="5.5892E+45"
        ixy="-4.0943E+45"
        ixz="-7.2564E+44"
        iyy="3.2636E+45"
        iyz="-9.6042E+44"
        izz="8.5124E+45" />
    </inertial>
    <visual>
      <origin
        xyz="0 0 0"
        rpy="0 0 0" />
      <geometry>
        <mesh
          filename="package://robot_description/meshes/Link2.STL" />
      </geometry>
      <material
        name="">
        <color
          rgba="1 1 1 1" />
      </material>
    </visual>
    <collision>
      <origin
        xyz="0 0 0"
        rpy="0 0 0" />
      <geometry>
        <mesh
          filename="package://robot_description/meshes/Link2.STL" />
      </geometry>
    </collision>
  </link>
  <joint
    name="joint_2"
    type="revolute">
    <origin
      xyz="0.24994 0.239 0.29844"
      rpy="-1.5708 0 0" />
    <parent
      link="Link1" />
    <child
      link="Link2" />
    <axis
      xyz="0 0 -1" />
    <limit
      lower="-2.0071"
      upper="2.094"
      effort="100000"
      velocity="2" />
  </joint>
  <link
    name="Link3">
    <inertial>
      <origin
        xyz="0.0295766895166405 -0.0440500878929433 0.244531620234894"
        rpy="0 0 0" />
      <mass
        value="54.8497239391138" />
      <inertia
        ixx="1.57769910645969"
        ixy="0.224580870519169"
        ixz="-0.0606303870690732"
        iyy="1.27119892970626"
        iyz="0.0789769466616716"
        izz="1.28753475738862" />
    </inertial>
    <visual>
      <origin
        xyz="0 0 0"
        rpy="0 0 0" />
      <geometry>
        <mesh
          filename="package://robot_description/meshes/Link3.STL" />
      </geometry>
      <material
        name="">
        <color
          rgba="1 1 1 1" />
      </material>
    </visual>
    <collision>
      <origin
        xyz="0 0 0"
        rpy="0 0 0" />
      <geometry>
        <mesh
          filename="package://robot_description/meshes/Link3.STL" />
      </geometry>
    </collision>
  </link>
  <joint
    name="joint_3"
    type="revolute">
    <origin
      xyz="8.587E-05 -0.95252 0.04995"
      rpy="-3.1416 0 0" />
    <parent
      link="Link2" />
    <child
      link="Link3" />
    <axis
      xyz="0 0 -1" />
    <limit
      lower="-2.443"
      upper="2.53"
      effort="100000"
      velocity="2" />
  </joint>
  <link
    name="Link4">
    <inertial>
      <origin
        xyz="-0.0017742167367687 0.00510255610352519 0.324104531535401"
        rpy="0 0 0" />
      <mass
        value="32.6033860752865" />
      <inertia
        ixx="1.48753181974762"
        ixy="-0.000551665245867233"
        ixz="0.00197255156966189"
        iyy="1.35887057122941"
        iyz="-0.0549721505149915"
        izz="0.353593775329007" />
    </inertial>
    <visual>
      <origin
        xyz="0 0 0"
        rpy="0 0 0" />
      <geometry>
        <mesh
          filename="package://robot_description/meshes/Link4.STL" />
      </geometry>
      <material
        name="">
        <color
          rgba="1 1 1 1" />
      </material>
    </visual>
    <collision>
      <origin
        xyz="0 0 0"
        rpy="0 0 0" />
      <geometry>
        <mesh
          filename="package://robot_description/meshes/Link4.STL" />
      </geometry>
    </collision>
  </link>
  <joint
    name="joint_4"
    type="revolute">
    <origin
      xyz="-0.00011402 0.17664 0.28895"
      rpy="-1.5708 0 0" />
    <parent
      link="Link3" />
    <child
      link="Link4" />
    <axis
      xyz="0 0 -1" />
    <limit
      lower="-4.7123"
      upper="4.7123"
      effort="100000"
      velocity="2" />
  </joint>
  <link
    name="Link5">
    <inertial>
      <origin
        xyz="2.26929819879818E-05 -0.0493393380570577 -0.0797818987385228"
        rpy="0 0 0" />
      <mass
        value="5.30907305737881" />
      <inertia
        ixx="0.040378596382921"
        ixy="6.86120279421567E-06"
        ixz="3.92870699069878E-06"
        iyy="0.0164747799847275"
        iyz="-0.000153178723827858"
        izz="0.0399298921183855" />
    </inertial>
    <visual>
      <origin
        xyz="0 0 0"
        rpy="0 0 0" />
      <geometry>
        <mesh
          filename="package://robot_description/meshes/Link5.STL" />
      </geometry>
      <material
        name="">
        <color
          rgba="1 1 1 1" />
      </material>
    </visual>
    <collision>
      <origin
        xyz="0 0 0"
        rpy="0 0 0" />
      <geometry>
        <mesh
          filename="package://robot_description/meshes/Link5.STL" />
      </geometry>
    </collision>
  </link>
  <joint
    name="joint_5"
    type="revolute">
    <origin
      xyz="8.9662E-05 0.0785 0.62217"
      rpy="-1.5708 0 0" />
    <parent
      link="Link4" />
    <child
      link="Link5" />
    <axis
      xyz="0 0 -1" />
    <limit
      lower="-2.094"
      upper="2.094"
      effort="100000"
      velocity="2" />
  </joint>
  <link
    name="Link6">
    <inertial>
      <origin
        xyz="0.00025833309019499 -2.06849144375465E-08 -0.0126692850546037"
        rpy="0 0 0" />
      <mass
        value="0.205963576921912" />
      <inertia
        ixx="0.000189932098659272"
        ixy="2.10613190161523E-09"
        ixz="1.82397539372542E-07"
        iyy="0.000188825315775277"
        iyz="2.01174206869031E-11"
        izz="0.000359577566804308" />
    </inertial>
    <visual>
      <origin
        xyz="0 0 0"
        rpy="0 0 0" />
      <geometry>
        <mesh
          filename="package://robot_description/meshes/Link6.STL" />
      </geometry>
      <material
        name="">
        <color
          rgba="1 1 1 1" />
      </material>
    </visual>
    <collision>
      <origin
        xyz="0 0 0"
        rpy="0 0 0" />
      <geometry>
        <mesh
          filename="package://robot_description/meshes/Link6.STL" />
      </geometry>
    </collision>
  </link>
  <joint
    name="joint_6"
    type="revolute">
    <origin
      xyz="-0.00036826 -0.20708 -0.0805"
      rpy="1.5708 0 0" />
    <parent
      link="Link5" />
    <child
      link="Link6" />
    <axis
      xyz="0 0 -1" />
    <limit
      lower="-4.7123"
      upper="4.7123"
      effort="10000"
      velocity="2" />
  </joint>

<!-- Gazebo color -->
  <gazebo reference="base_link">
      <material>Gazebo/White</material>
  </gazebo>
  <gazebo reference="Link1">
      <material>Gazebo/White</material>
  </gazebo>
  <gazebo reference="Link2">
      <material>Gazebo/White</material>
  </gazebo>
  <gazebo reference="Link3">
      <material>Gazebo/White</material>
  </gazebo>
  <gazebo reference="Link4">
      <material>Gazebo/White</material>
  </gazebo>
  <gazebo reference="Link5">
      <material>Gazebo/White</material>
  </gazebo>
  <gazebo reference="Link6">
      <material>Gazebo/White</material>
  </gazebo>

<!-- Transmissions for ROS Control -->
  <xacro:macro name="transmission_block" params="joint_name">
      <transmission name="${joint_name}_trans">
          <type>transmission_interface/SimpleTransmission</type>
          <joint name="${joint_name}">
              <hardwareInterface>hardware_interface/PositionJointInterface</hardwareInterface>
          </joint>
          <actuator name="{joint_name}_motor">
              <hardwareInterface>hardware_interface/PositionJointInterface</hardwareInterface>
              <mechanicalReduction>1</mechanicalReduction>
          </actuator>
      </transmission>
  </xacro:macro>
    
  <xacro:transmission_block joint_name="joint_1"/>
  <xacro:transmission_block joint_name="joint_2"/>
  <xacro:transmission_block joint_name="joint_3"/>
  <xacro:transmission_block joint_name="joint_4"/>
  <xacro:transmission_block joint_name="joint_5"/>
  <xacro:transmission_block joint_name="joint_6"/>

<!-- ros_control plugin -->
  <gazebo>
      <plugin name="gazebo_ros_control" filename="libgazebo_ros_control.so">
          <robotNamespace>/stab</robotNamespace>
          <legacyModeNS>true</legacyModeNS>
      </plugin>
  </gazebo>

</robot>
